{"timestamp": "2025-08-12T10:11:36.786768", "level": "ERROR", "logger": "scrollintel.core.performance_monitor", "message": "Request error in POST /api/error: Test error", "module": "logging_config", "function": "error", "line": 227, "process_id": 21520, "thread_id": 6596}
{"timestamp": "2025-08-12T10:11:37.959845", "level": "ERROR", "logger": "scrollintel.core.performance_monitor", "message": "Database query error: SQL error", "module": "logging_config", "function": "error", "line": 227, "process_id": 21520, "thread_id": 6596}
{"timestamp": "2025-08-13T20:34:40.487927", "level": "ERROR", "logger": "scrollintel.models.database_utils", "message": "Failed to initialize database manager: [WinError 1225] The remote computer refused the network connection", "module": "database_utils", "function": "initialize", "line": 88, "process_id": 6628, "thread_id": 32464}
{"timestamp": "2025-08-13T20:34:40.489259", "level": "ERROR", "logger": "scrollintel.core.audit_system", "message": "Failed to save audit event: Database initialization failed: [WinError 1225] The remote computer refused the network connection", "module": "logging_config", "function": "error", "line": 227, "process_id": 6628, "thread_id": 32464}
{"timestamp": "2025-08-13T20:34:40.490559", "level": "ERROR", "logger": "scrollintel.core.audit_system", "message": "Failed to save audit event: One or more mappers failed to initialize - can't proceed with initialization of other mappers. Triggering mapper: 'Mapper[User(users)]'. Original exception was: When initializing mapper Mapper[User(users)], expression 'UserAuditLog' failed to locate a name ('UserAuditLog'). If this is a class name, consider adding this relationship() to the <class 'scrollintel.models.database.User'> class after both dependent classes have been defined.", "module": "logging_config", "function": "error", "line": 227, "process_id": 6628, "thread_id": 32464}
{"timestamp": "2025-08-13T20:34:40.491346", "level": "ERROR", "logger": "scrollintel.core.audit_system", "message": "Failed to save audit event: One or more mappers failed to initialize - can't proceed with initialization of other mappers. Triggering mapper: 'Mapper[User(users)]'. Original exception was: When initializing mapper Mapper[User(users)], expression 'UserAuditLog' failed to locate a name ('UserAuditLog'). If this is a class name, consider adding this relationship() to the <class 'scrollintel.models.database.User'> class after both dependent classes have been defined.", "module": "logging_config", "function": "error", "line": 227, "process_id": 6628, "thread_id": 32464}
{"timestamp": "2025-08-13T20:34:40.511021", "level": "ERROR", "logger": "scrollintel.core.audit_system", "message": "Failed to save audit event: One or more mappers failed to initialize - can't proceed with initialization of other mappers. Triggering mapper: 'Mapper[User(users)]'. Original exception was: When initializing mapper Mapper[User(users)], expression 'UserAuditLog' failed to locate a name ('UserAuditLog'). If this is a class name, consider adding this relationship() to the <class 'scrollintel.models.database.User'> class after both dependent classes have been defined.", "module": "logging_config", "function": "error", "line": 227, "process_id": 6628, "thread_id": 32464}
{"timestamp": "2025-08-13T20:34:40.511848", "level": "ERROR", "logger": "scrollintel.core.audit_system", "message": "Failed to save audit event: One or more mappers failed to initialize - can't proceed with initialization of other mappers. Triggering mapper: 'Mapper[User(users)]'. Original exception was: When initializing mapper Mapper[User(users)], expression 'UserAuditLog' failed to locate a name ('UserAuditLog'). If this is a class name, consider adding this relationship() to the <class 'scrollintel.models.database.User'> class after both dependent classes have been defined.", "module": "logging_config", "function": "error", "line": 227, "process_id": 6628, "thread_id": 32464}
{"timestamp": "2025-08-13T20:34:44.579174", "level": "ERROR", "logger": "scrollintel.core.compliance_manager", "message": "Error applying retention policy audit_logs_standard: [WinError 1225] The remote computer refused the network connection", "module": "logging_config", "function": "error", "line": 227, "process_id": 6628, "thread_id": 32464}
{"timestamp": "2025-08-15T01:59:17.218857", "level": "ERROR", "logger": "scrollintel.core.background_jobs", "message": "Failed to initialize job processor: Error Multiple exceptions: [Errno 10061] Connect call failed ('::1', 6379, 0, 0), [Errno 10061] Connect call failed ('127.0.0.1', 6379) connecting to localhost:6379.", "module": "background_jobs", "function": "initialize", "line": 365, "process_id": 32392, "thread_id": 32320}
{"timestamp": "2025-08-15T02:00:49.434924", "level": "ERROR", "logger": "scrollintel.models.database_utils", "message": "Failed to initialize database manager: Multiple exceptions: [Errno 10061] Connect call failed ('::1', 5432, 0, 0), [Errno 10061] Connect call failed ('127.0.0.1', 5432)", "module": "database_utils", "function": "initialize", "line": 88, "process_id": 32392, "thread_id": 32320}
{"timestamp": "2025-08-15T02:00:49.435956", "level": "ERROR", "logger": "scrollintel.core.audit_system", "message": "Failed to save audit event: Database initialization failed: Multiple exceptions: [Errno 10061] Connect call failed ('::1', 5432, 0, 0), [Errno 10061] Connect call failed ('127.0.0.1', 5432)", "module": "logging_config", "function": "error", "line": 227, "process_id": 32392, "thread_id": 32320}
