"""
Chaos Engineering Test Suite for Bulletproof User Experience

This module implements comprehensive chaos engineering tests that inject various
types of failures to validate the bulletproof system's resilience and recovery capabilities.
"""

import asyncio
import pytest
import random
import time
from unittest.mock import Mock, patch, AsyncMock
from typing import Dict, List, Any, Optional
import logging

try:
    from scrollintel.core.bulletproof_orchestrator import BulletproofOrchestrator
except ImportError:
    from unittest.mock import AsyncMock
    BulletproofOrchestrator = AsyncMock

try:
    from scrollintel.core.failure_prevention import FailurePreventionSystem as FailurePreventionManager
except ImportError:
    from unittest.mock import AsyncMock
    FailurePreventionManager = AsyncMock

try:
    from scrollintel.core.graceful_degradation import GracefulDegradationManager
except ImportError:
    from unittest.mock import AsyncMock
    GracefulDegradationManager = AsyncMock

try:
    from scrollintel.core.user_experience_protection import UserExperienceProtector
except ImportError:
    from unittest.mock import AsyncMock
    UserExperienceProtector = AsyncMock

try:
    from scrollintel.core.never_fail_decorators import never_fail
except ImportError:
    def never_fail(func):
        return func


class ChaosEngineeringTestSuite:
    """Comprehensive chaos engineering test suite for bulletproof system validation."""
    
    def __init__(self):
        self.orchestrator = BulletproofOrchestrator()
        self.failure_prevention = FailurePreventionManager()
        self.degradation_manager = GracefulDegradationManager()
        self.ux_protector = UserExperienceProtector()
        self.test_results = []
        
    async def inject_network_failure(self, duration: int = 5):
        """Inject network connectivity failures."""
        with patch('aiohttp.ClientSession.get') as mock_get:
            mock_get.side_effect = asyncio.TimeoutError("Network timeout")
            await asyncio.sleep(duration)
            
    async def inject_database_failure(self, duration: int = 3):
        """Inject database connectivity failures."""
        with patch('sqlalchemy.engine.Engine.connect') as mock_connect:
            mock_connect.side_effect = Exception("Database connection failed")
            await asyncio.sleep(duration)
            
    async def inject_memory_pressure(self, duration: int = 10):
        """Simulate high memory usage conditions."""
        # Simulate memory pressure by creating large objects
        memory_hog = []
        try:
            for _ in range(1000):
                memory_hog.append([0] * 10000)
                await asyncio.sleep(0.01)
            await asyncio.sleep(duration)
        finally:
            del memory_hog
            
    async def inject_cpu_stress(self, duration: int = 5):
        """Simulate high CPU usage conditions."""
        start_time = time.time()
        while time.time() - start_time < duration:
            # CPU-intensive operation
            sum(i * i for i in range(1000))
            await asyncio.sleep(0.001)


@pytest.mark.asyncio
class TestChaosEngineering:
    """Test suite for chaos engineering scenarios."""
    
    @pytest.fixture
    def chaos_suite(self):
        return ChaosEngineeringTestSuite()
        
    async def test_network_failure_resilience(self, chaos_suite):
        """Test system resilience during network failures."""
        # Start network failure injection
        failure_task = asyncio.create_task(
            chaos_suite.inject_network_failure(duration=5)
        )
        
        # Attempt operations during network failure
        results = []
        for i in range(10):
            try:
                result = await chaos_suite.orchestrator.handle_user_action({
                    'action': 'fetch_data',
                    'user_id': f'test_user_{i}',
                    'timestamp': time.time()
                })
                results.append(result)
            except Exception as e:
                results.append({'error': str(e), 'fallback_used': True})
                
        await failure_task
        
        # Verify all operations completed with fallbacks
        assert len(results) == 10
        successful_operations = sum(1 for r in results if r.get('success', False) or r.get('fallback_used', False))
        assert successful_operations >= 8, "Should maintain 80% success rate during network failures"
        
    async def test_database_failure_recovery(self, chaos_suite):
        """Test automatic recovery from database failures."""
        # Inject database failure
        failure_task = asyncio.create_task(
            chaos_suite.inject_database_failure(duration=3)
        )
        
        # Test data operations during failure
        operations = []
        for i in range(5):
            operation = await chaos_suite.ux_protector.protect_data_operation({
                'operation': 'save_user_data',
                'user_id': f'user_{i}',
                'data': {'test': f'data_{i}'}
            })
            operations.append(operation)
            
        await failure_task
        
        # Verify operations were protected
        for op in operations:
            assert op.get('protected', False), "All operations should be protected"
            assert op.get('fallback_used', False) or op.get('cached', False), "Should use fallbacks or caching"
            
    async def test_memory_pressure_degradation(self, chaos_suite):
        """Test graceful degradation under memory pressure."""
        # Start memory pressure
        pressure_task = asyncio.create_task(
            chaos_suite.inject_memory_pressure(duration=10)
        )
        
        # Monitor degradation levels
        degradation_levels = []
        for i in range(5):
            level = await chaos_suite.degradation_manager.assess_current_degradation()
            degradation_levels.append(level)
            await asyncio.sleep(2)
            
        await pressure_task
        
        # Verify degradation was applied appropriately
        assert any(level > 0 for level in degradation_levels), "Should apply degradation under pressure"
        
    async def test_cpu_stress_performance_optimization(self, chaos_suite):
        """Test performance optimization under CPU stress."""
        # Start CPU stress
        stress_task = asyncio.create_task(
            chaos_suite.inject_cpu_stress(duration=5)
        )
        
        # Measure response times
        response_times = []
        for i in range(10):
            start_time = time.time()
            await chaos_suite.orchestrator.optimize_performance({
                'operation': 'complex_calculation',
                'complexity': 'high'
            })
            response_time = time.time() - start_time
            response_times.append(response_time)
            
        await stress_task
        
        # Verify performance optimization kicked in
        avg_response_time = sum(response_times) / len(response_times)
        assert avg_response_time < 2.0, "Should maintain reasonable response times under stress"
        
    async def test_cascading_failure_prevention(self, chaos_suite):
        """Test prevention of cascading failures."""
        # Simulate multiple simultaneous failures
        failures = [
            chaos_suite.inject_network_failure(3),
            chaos_suite.inject_database_failure(2),
            chaos_suite.inject_memory_pressure(5)
        ]
        
        failure_tasks = [asyncio.create_task(f) for f in failures]
        
        # Test system stability during multiple failures
        stability_checks = []
        for i in range(10):
            check = await chaos_suite.failure_prevention.check_system_stability()
            stability_checks.append(check)
            await asyncio.sleep(0.5)
            
        await asyncio.gather(*failure_tasks)
        
        # Verify system remained stable
        stable_checks = sum(1 for check in stability_checks if check.get('stable', False))
        assert stable_checks >= 7, "System should remain stable during cascading failures"
        
    async def test_recovery_time_validation(self, chaos_suite):
        """Test that recovery times meet SLA requirements."""
        # Inject failure and measure recovery time
        start_time = time.time()
        
        # Simulate service failure
        with patch('scrollintel.core.bulletproof_orchestrator.BulletproofOrchestrator.check_service_health') as mock_health:
            mock_health.return_value = {'healthy': False, 'service': 'test_service'}
            
            # Trigger recovery
            recovery_result = await chaos_suite.orchestrator.trigger_auto_recovery('test_service')
            
        recovery_time = time.time() - start_time
        
        # Verify recovery time meets requirements (< 30 seconds)
        assert recovery_time < 30, f"Recovery took {recovery_time}s, should be < 30s"
        assert recovery_result.get('success', False), "Recovery should succeed"
        
    async def test_user_experience_continuity(self, chaos_suite):
        """Test that user experience remains continuous during failures."""
        # Simulate user session during various failures
        user_session = {
            'user_id': 'test_user_continuity',
            'session_id': 'session_123',
            'current_task': 'data_analysis'
        }
        
        # Inject random failures
        failure_types = [
            chaos_suite.inject_network_failure(2),
            chaos_suite.inject_database_failure(1),
            chaos_suite.inject_memory_pressure(3)
        ]
        
        selected_failure = random.choice(failure_types)
        failure_task = asyncio.create_task(selected_failure)
        
        # Test user operations during failure
        user_operations = []
        for i in range(5):
            operation = await chaos_suite.ux_protector.ensure_user_continuity(
                user_session, f'operation_{i}'
            )
            user_operations.append(operation)
            
        await failure_task
        
        # Verify user experience continuity
        for op in user_operations:
            assert op.get('continuity_maintained', False), "User continuity should be maintained"
            assert op.get('user_notified', False) or op.get('transparent', True), "User should be informed or operation should be transparent"


@pytest.mark.asyncio
class TestFailureInjection:
    """Advanced failure injection tests."""
    
    async def test_random_component_failures(self):
        """Test random component failure scenarios."""
        components = [
            'api_gateway', 'database', 'cache', 'message_queue',
            'file_storage', 'authentication', 'analytics'
        ]
        
        orchestrator = BulletproofOrchestrator()
        
        # Randomly fail components
        failed_components = random.sample(components, 3)
        
        for component in failed_components:
            with patch(f'scrollintel.core.{component}.health_check') as mock_health:
                mock_health.return_value = False
                
                # Test system response to component failure
                response = await orchestrator.handle_component_failure(component)
                
                assert response.get('handled', False), f"Should handle {component} failure"
                assert response.get('fallback_active', False), f"Should activate fallback for {component}"
                
    async def test_intermittent_failures(self):
        """Test handling of intermittent, flaky failures."""
        orchestrator = BulletproofOrchestrator()
        
        # Simulate intermittent failures
        failure_count = 0
        
        def intermittent_failure(*args, **kwargs):
            nonlocal failure_count
            failure_count += 1
            if failure_count % 3 == 0:  # Fail every 3rd call
                raise Exception("Intermittent failure")
            return {'success': True}
            
        with patch('scrollintel.core.bulletproof_orchestrator.BulletproofOrchestrator.call_service') as mock_call:
            mock_call.side_effect = intermittent_failure
            
            # Make multiple calls
            results = []
            for i in range(10):
                result = await orchestrator.resilient_service_call('test_service', {})
                results.append(result)
                
        # Verify intermittent failures were handled
        successful_calls = sum(1 for r in results if r.get('success', False))
        assert successful_calls >= 7, "Should handle intermittent failures gracefully"
        
    async def test_data_corruption_scenarios(self):
        """Test handling of data corruption scenarios."""
        ux_protector = UserExperienceProtector()
        
        # Simulate corrupted data
        corrupted_data = {
            'user_id': None,  # Missing required field
            'data': {'invalid': float('inf')},  # Invalid data
            'timestamp': 'invalid_timestamp'  # Wrong type
        }
        
        # Test data protection
        protected_result = await ux_protector.protect_data_integrity(corrupted_data)
        
        assert protected_result.get('data_protected', False), "Should protect against corrupted data"
        assert protected_result.get('fallback_data', None) is not None, "Should provide fallback data"
        assert protected_result.get('user_notified', False), "Should notify user of data issues"


if __name__ == "__main__":
    # Run chaos engineering tests
    pytest.main([__file__, "-v", "--asyncio-mode=auto"])